[2024-10-24T01:26:58.592+0000] {taskinstance.py:1157} INFO - Dependencies all met for dep_context=non-requeueable deps ti=<TaskInstance: api_openbrewerydb_to_silver_gold.Silver scheduled__2023-12-03T08:00:00+00:00 [queued]>
[2024-10-24T01:26:58.613+0000] {taskinstance.py:1157} INFO - Dependencies all met for dep_context=requeueable deps ti=<TaskInstance: api_openbrewerydb_to_silver_gold.Silver scheduled__2023-12-03T08:00:00+00:00 [queued]>
[2024-10-24T01:26:58.614+0000] {taskinstance.py:1359} INFO - Starting attempt 1 of 3
[2024-10-24T01:26:58.860+0000] {taskinstance.py:1380} INFO - Executing <Task(SparkSubmitOperator): Silver> on 2023-12-03 08:00:00+00:00
[2024-10-24T01:26:58.869+0000] {standard_task_runner.py:57} INFO - Started process 8908 to run task
[2024-10-24T01:26:58.884+0000] {standard_task_runner.py:84} INFO - Running: ['***', 'tasks', 'run', 'api_openbrewerydb_to_silver_gold', 'Silver', 'scheduled__2023-12-03T08:00:00+00:00', '--job-id', '142', '--raw', '--subdir', 'DAGS_FOLDER/api_openbrewerydb_to_silver.py', '--cfg-path', '/tmp/tmpwi4bf76d']
[2024-10-24T01:26:58.903+0000] {standard_task_runner.py:85} INFO - Job 142: Subtask Silver
[2024-10-24T01:26:59.121+0000] {task_command.py:415} INFO - Running <TaskInstance: api_openbrewerydb_to_silver_gold.Silver scheduled__2023-12-03T08:00:00+00:00 [running]> on host de5108c6da1d
[2024-10-24T01:26:59.501+0000] {taskinstance.py:1660} INFO - Exporting env vars: AIRFLOW_CTX_DAG_OWNER='Rodrigo Araujo' AIRFLOW_CTX_DAG_ID='api_openbrewerydb_to_silver_gold' AIRFLOW_CTX_TASK_ID='Silver' AIRFLOW_CTX_EXECUTION_DATE='2023-12-03T08:00:00+00:00' AIRFLOW_CTX_TRY_NUMBER='1' AIRFLOW_CTX_DAG_RUN_ID='scheduled__2023-12-03T08:00:00+00:00'
[2024-10-24T01:26:59.576+0000] {base.py:73} INFO - Using connection ID 'spark-conn' for task execution.
[2024-10-24T01:26:59.578+0000] {spark_submit.py:363} INFO - Spark-Submit cmd: spark-submit --master spark://spark-master:7077 --name arrow-spark --queue root.default jobs/silver/api_openbrewerydb.py
[2024-10-24T01:27:30.186+0000] {spark_submit.py:524} INFO - 24/10/24 01:27:30 INFO SparkContext: Running Spark version 3.5.3
[2024-10-24T01:27:30.192+0000] {spark_submit.py:524} INFO - 24/10/24 01:27:30 INFO SparkContext: OS info Linux, 5.15.0-124-generic, amd64
[2024-10-24T01:27:30.204+0000] {spark_submit.py:524} INFO - 24/10/24 01:27:30 INFO SparkContext: Java version 11.0.25
[2024-10-24T01:27:30.957+0000] {spark_submit.py:524} INFO - 24/10/24 01:27:30 WARN NativeCodeLoader: Unable to load native-hadoop library for your platform... using builtin-java classes where applicable
[2024-10-24T01:27:31.790+0000] {spark_submit.py:524} INFO - 24/10/24 01:27:31 INFO ResourceUtils: ==============================================================
[2024-10-24T01:27:31.792+0000] {spark_submit.py:524} INFO - 24/10/24 01:27:31 INFO ResourceUtils: No custom resources configured for spark.driver.
[2024-10-24T01:27:31.795+0000] {spark_submit.py:524} INFO - 24/10/24 01:27:31 INFO ResourceUtils: ==============================================================
[2024-10-24T01:27:31.798+0000] {spark_submit.py:524} INFO - 24/10/24 01:27:31 INFO SparkContext: Submitted application: IngestaoSilver
[2024-10-24T01:27:32.036+0000] {spark_submit.py:524} INFO - 24/10/24 01:27:32 INFO ResourceProfile: Default ResourceProfile created, executor resources: Map(memory -> name: memory, amount: 1024, script: , vendor: , offHeap -> name: offHeap, amount: 0, script: , vendor: ), task resources: Map(cpus -> name: cpus, amount: 1.0)
[2024-10-24T01:27:32.219+0000] {spark_submit.py:524} INFO - 24/10/24 01:27:32 INFO ResourceProfile: Limiting resource is cpu
[2024-10-24T01:27:32.222+0000] {spark_submit.py:524} INFO - 24/10/24 01:27:32 INFO ResourceProfileManager: Added ResourceProfile id: 0
[2024-10-24T01:27:32.996+0000] {spark_submit.py:524} INFO - 24/10/24 01:27:32 INFO SecurityManager: Changing view acls to: ***
[2024-10-24T01:27:32.999+0000] {spark_submit.py:524} INFO - 24/10/24 01:27:32 INFO SecurityManager: Changing modify acls to: ***
[2024-10-24T01:27:33.011+0000] {spark_submit.py:524} INFO - 24/10/24 01:27:33 INFO SecurityManager: Changing view acls groups to:
[2024-10-24T01:27:33.013+0000] {spark_submit.py:524} INFO - 24/10/24 01:27:33 INFO SecurityManager: Changing modify acls groups to:
[2024-10-24T01:27:33.029+0000] {spark_submit.py:524} INFO - 24/10/24 01:27:33 INFO SecurityManager: SecurityManager: authentication disabled; ui acls disabled; users with view permissions: ***; groups with view permissions: EMPTY; users with modify permissions: ***; groups with modify permissions: EMPTY
[2024-10-24T01:27:36.315+0000] {spark_submit.py:524} INFO - 24/10/24 01:27:36 INFO Utils: Successfully started service 'sparkDriver' on port 39875.
[2024-10-24T01:27:36.550+0000] {spark_submit.py:524} INFO - 24/10/24 01:27:36 INFO SparkEnv: Registering MapOutputTracker
[2024-10-24T01:27:36.974+0000] {spark_submit.py:524} INFO - 24/10/24 01:27:36 INFO SparkEnv: Registering BlockManagerMaster
[2024-10-24T01:27:37.276+0000] {spark_submit.py:524} INFO - 24/10/24 01:27:37 INFO BlockManagerMasterEndpoint: Using org.apache.spark.storage.DefaultTopologyMapper for getting topology information
[2024-10-24T01:27:37.278+0000] {spark_submit.py:524} INFO - 24/10/24 01:27:37 INFO BlockManagerMasterEndpoint: BlockManagerMasterEndpoint up
[2024-10-24T01:27:37.324+0000] {spark_submit.py:524} INFO - 24/10/24 01:27:37 INFO SparkEnv: Registering BlockManagerMasterHeartbeat
[2024-10-24T01:27:37.587+0000] {spark_submit.py:524} INFO - 24/10/24 01:27:37 INFO DiskBlockManager: Created local directory at /tmp/blockmgr-0cd14b49-8610-45c8-b046-0d20b929cfdf
[2024-10-24T01:27:37.647+0000] {spark_submit.py:524} INFO - 24/10/24 01:27:37 INFO MemoryStore: MemoryStore started with capacity 434.4 MiB
[2024-10-24T01:27:37.760+0000] {spark_submit.py:524} INFO - 24/10/24 01:27:37 INFO SparkEnv: Registering OutputCommitCoordinator
[2024-10-24T01:27:39.391+0000] {spark_submit.py:524} INFO - 24/10/24 01:27:39 INFO JettyUtils: Start Jetty 0.0.0.0:4040 for SparkUI
[2024-10-24T01:27:39.707+0000] {spark_submit.py:524} INFO - 24/10/24 01:27:39 WARN Utils: Service 'SparkUI' could not bind on port 4040. Attempting port 4041.
[2024-10-24T01:27:39.709+0000] {spark_submit.py:524} INFO - 24/10/24 01:27:39 WARN Utils: Service 'SparkUI' could not bind on port 4041. Attempting port 4042.
[2024-10-24T01:27:39.710+0000] {spark_submit.py:524} INFO - 24/10/24 01:27:39 WARN Utils: Service 'SparkUI' could not bind on port 4042. Attempting port 4043.
[2024-10-24T01:27:39.732+0000] {spark_submit.py:524} INFO - 24/10/24 01:27:39 WARN Utils: Service 'SparkUI' could not bind on port 4043. Attempting port 4044.
[2024-10-24T01:27:39.748+0000] {spark_submit.py:524} INFO - 24/10/24 01:27:39 WARN Utils: Service 'SparkUI' could not bind on port 4044. Attempting port 4045.
[2024-10-24T01:27:39.753+0000] {spark_submit.py:524} INFO - 24/10/24 01:27:39 WARN Utils: Service 'SparkUI' could not bind on port 4045. Attempting port 4046.
[2024-10-24T01:27:39.754+0000] {spark_submit.py:524} INFO - 24/10/24 01:27:39 WARN Utils: Service 'SparkUI' could not bind on port 4046. Attempting port 4047.
[2024-10-24T01:27:39.764+0000] {spark_submit.py:524} INFO - 24/10/24 01:27:39 WARN Utils: Service 'SparkUI' could not bind on port 4047. Attempting port 4048.
[2024-10-24T01:27:39.830+0000] {spark_submit.py:524} INFO - 24/10/24 01:27:39 INFO Utils: Successfully started service 'SparkUI' on port 4048.
[2024-10-24T01:27:41.862+0000] {spark_submit.py:524} INFO - 24/10/24 01:27:41 INFO StandaloneAppClient$ClientEndpoint: Connecting to master spark://spark-master:7077...
[2024-10-24T01:27:42.270+0000] {spark_submit.py:524} INFO - 24/10/24 01:27:42 INFO TransportClientFactory: Successfully created connection to spark-master/172.22.0.3:7077 after 252 ms (0 ms spent in bootstraps)
[2024-10-24T01:27:45.281+0000] {spark_submit.py:524} INFO - 24/10/24 01:27:45 INFO StandaloneSchedulerBackend: Connected to Spark cluster with app ID app-20241024012743-0049
[2024-10-24T01:27:56.408+0000] {spark_submit.py:524} INFO - 24/10/24 01:27:56 INFO Utils: Successfully started service 'org.apache.spark.network.netty.NettyBlockTransferService' on port 42349.
[2024-10-24T01:27:56.649+0000] {spark_submit.py:524} INFO - 24/10/24 01:27:56 INFO NettyBlockTransferService: Server created on de5108c6da1d:42349
[2024-10-24T01:27:56.921+0000] {spark_submit.py:524} INFO - 24/10/24 01:27:56 INFO BlockManager: Using org.apache.spark.storage.RandomBlockReplicationPolicy for block replication policy
[2024-10-24T01:28:06.380+0000] {spark_submit.py:524} INFO - 24/10/24 01:28:04 INFO BlockManagerMaster: Registering BlockManager BlockManagerId(driver, de5108c6da1d, 42349, None)
[2024-10-24T01:28:15.603+0000] {spark_submit.py:524} INFO - 24/10/24 01:28:14 INFO BlockManagerMasterEndpoint: Registering block manager de5108c6da1d:42349 with 434.4 MiB RAM, BlockManagerId(driver, de5108c6da1d, 42349, None)
[2024-10-24T01:28:56.922+0000] {spark_submit.py:524} INFO - 24/10/24 01:28:56 INFO BlockManagerMaster: Registered BlockManager BlockManagerId(driver, de5108c6da1d, 42349, None)
[2024-10-24T01:28:58.424+0000] {spark_submit.py:524} INFO - 24/10/24 01:28:58 INFO BlockManager: Initialized BlockManager: BlockManagerId(driver, de5108c6da1d, 42349, None)
[2024-10-24T01:28:45.255+0000] {job.py:219} ERROR - Job heartbeat got an exception
Traceback (most recent call last):
  File "/home/airflow/.local/lib/python3.11/site-packages/sqlalchemy/engine/base.py", line 3371, in _wrap_pool_connect
    return fn()
           ^^^^
  File "/home/airflow/.local/lib/python3.11/site-packages/sqlalchemy/pool/base.py", line 327, in connect
    return _ConnectionFairy._checkout(self)
           ^^^^^^^^^^^^^^^^^^^^^^^^^^^^^^^^
  File "/home/airflow/.local/lib/python3.11/site-packages/sqlalchemy/pool/base.py", line 894, in _checkout
    fairy = _ConnectionRecord.checkout(pool)
            ^^^^^^^^^^^^^^^^^^^^^^^^^^^^^^^^
  File "/home/airflow/.local/lib/python3.11/site-packages/sqlalchemy/pool/base.py", line 493, in checkout
    rec = pool._do_get()
          ^^^^^^^^^^^^^^
  File "/home/airflow/.local/lib/python3.11/site-packages/sqlalchemy/pool/impl.py", line 256, in _do_get
    return self._create_connection()
           ^^^^^^^^^^^^^^^^^^^^^^^^^
  File "/home/airflow/.local/lib/python3.11/site-packages/sqlalchemy/pool/base.py", line 273, in _create_connection
    return _ConnectionRecord(self)
           ^^^^^^^^^^^^^^^^^^^^^^^
  File "/home/airflow/.local/lib/python3.11/site-packages/sqlalchemy/pool/base.py", line 388, in __init__
    self.__connect()
  File "/home/airflow/.local/lib/python3.11/site-packages/sqlalchemy/pool/base.py", line 690, in __connect
    with util.safe_reraise():
  File "/home/airflow/.local/lib/python3.11/site-packages/sqlalchemy/util/langhelpers.py", line 70, in __exit__
    compat.raise_(
  File "/home/airflow/.local/lib/python3.11/site-packages/sqlalchemy/util/compat.py", line 211, in raise_
    raise exception
  File "/home/airflow/.local/lib/python3.11/site-packages/sqlalchemy/pool/base.py", line 686, in __connect
    self.dbapi_connection = connection = pool._invoke_creator(self)
                                         ^^^^^^^^^^^^^^^^^^^^^^^^^^
  File "/home/airflow/.local/lib/python3.11/site-packages/sqlalchemy/engine/create.py", line 574, in connect
    return dialect.connect(*cargs, **cparams)
           ^^^^^^^^^^^^^^^^^^^^^^^^^^^^^^^^^^
  File "/home/airflow/.local/lib/python3.11/site-packages/sqlalchemy/engine/default.py", line 598, in connect
    return self.dbapi.connect(*cargs, **cparams)
           ^^^^^^^^^^^^^^^^^^^^^^^^^^^^^^^^^^^^^
  File "/home/airflow/.local/lib/python3.11/site-packages/psycopg2/__init__.py", line 122, in connect
    conn = _connect(dsn, connection_factory=connection_factory, **kwasync)
           ^^^^^^^^^^^^^^^^^^^^^^^^^^^^^^^^^^^^^^^^^^^^^^^^^^^^^^^^^^^^^^^
psycopg2.OperationalError: could not translate host name "postgres" to address: Temporary failure in name resolution


The above exception was the direct cause of the following exception:

Traceback (most recent call last):
  File "/home/airflow/.local/lib/python3.11/site-packages/airflow/jobs/job.py", line 215, in heartbeat
    heartbeat_callback(session)
  File "/home/airflow/.local/lib/python3.11/site-packages/airflow/utils/session.py", line 74, in wrapper
    return func(*args, **kwargs)
           ^^^^^^^^^^^^^^^^^^^^^
  File "/home/airflow/.local/lib/python3.11/site-packages/airflow/jobs/local_task_job_runner.py", line 246, in heartbeat_callback
    self.task_instance.refresh_from_db()
  File "/home/airflow/.local/lib/python3.11/site-packages/airflow/utils/session.py", line 77, in wrapper
    return func(*args, session=session, **kwargs)
           ^^^^^^^^^^^^^^^^^^^^^^^^^^^^^^^^^^^^^^
  File "/home/airflow/.local/lib/python3.11/site-packages/airflow/models/taskinstance.py", line 864, in refresh_from_db
    ti = qry.one_or_none()
         ^^^^^^^^^^^^^^^^^
  File "/home/airflow/.local/lib/python3.11/site-packages/sqlalchemy/orm/query.py", line 2850, in one_or_none
    return self._iter().one_or_none()
           ^^^^^^^^^^^^
  File "/home/airflow/.local/lib/python3.11/site-packages/sqlalchemy/orm/query.py", line 2916, in _iter
    result = self.session.execute(
             ^^^^^^^^^^^^^^^^^^^^^
  File "/home/airflow/.local/lib/python3.11/site-packages/sqlalchemy/orm/session.py", line 1716, in execute
    conn = self._connection_for_bind(bind)
           ^^^^^^^^^^^^^^^^^^^^^^^^^^^^^^^
  File "/home/airflow/.local/lib/python3.11/site-packages/sqlalchemy/orm/session.py", line 1555, in _connection_for_bind
    return self._transaction._connection_for_bind(
           ^^^^^^^^^^^^^^^^^^^^^^^^^^^^^^^^^^^^^^^
  File "/home/airflow/.local/lib/python3.11/site-packages/sqlalchemy/orm/session.py", line 750, in _connection_for_bind
    conn = bind.connect()
           ^^^^^^^^^^^^^^
  File "/home/airflow/.local/lib/python3.11/site-packages/sqlalchemy/future/engine.py", line 406, in connect
    return super(Engine, self).connect()
           ^^^^^^^^^^^^^^^^^^^^^^^^^^^^^
  File "/home/airflow/.local/lib/python3.11/site-packages/sqlalchemy/engine/base.py", line 3325, in connect
    return self._connection_cls(self, close_with_result=close_with_result)
           ^^^^^^^^^^^^^^^^^^^^^^^^^^^^^^^^^^^^^^^^^^^^^^^^^^^^^^^^^^^^^^^
  File "/home/airflow/.local/lib/python3.11/site-packages/sqlalchemy/engine/base.py", line 96, in __init__
    else engine.raw_connection()
         ^^^^^^^^^^^^^^^^^^^^^^^
  File "/home/airflow/.local/lib/python3.11/site-packages/sqlalchemy/engine/base.py", line 3404, in raw_connection
    return self._wrap_pool_connect(self.pool.connect, _connection)
           ^^^^^^^^^^^^^^^^^^^^^^^^^^^^^^^^^^^^^^^^^^^^^^^^^^^^^^^
  File "/home/airflow/.local/lib/python3.11/site-packages/sqlalchemy/engine/base.py", line 3374, in _wrap_pool_connect
    Connection._handle_dbapi_exception_noconnection(
  File "/home/airflow/.local/lib/python3.11/site-packages/sqlalchemy/engine/base.py", line 2208, in _handle_dbapi_exception_noconnection
    util.raise_(
  File "/home/airflow/.local/lib/python3.11/site-packages/sqlalchemy/util/compat.py", line 211, in raise_
    raise exception
  File "/home/airflow/.local/lib/python3.11/site-packages/sqlalchemy/engine/base.py", line 3371, in _wrap_pool_connect
    return fn()
           ^^^^
  File "/home/airflow/.local/lib/python3.11/site-packages/sqlalchemy/pool/base.py", line 327, in connect
    return _ConnectionFairy._checkout(self)
           ^^^^^^^^^^^^^^^^^^^^^^^^^^^^^^^^
  File "/home/airflow/.local/lib/python3.11/site-packages/sqlalchemy/pool/base.py", line 894, in _checkout
    fairy = _ConnectionRecord.checkout(pool)
            ^^^^^^^^^^^^^^^^^^^^^^^^^^^^^^^^
  File "/home/airflow/.local/lib/python3.11/site-packages/sqlalchemy/pool/base.py", line 493, in checkout
    rec = pool._do_get()
          ^^^^^^^^^^^^^^
  File "/home/airflow/.local/lib/python3.11/site-packages/sqlalchemy/pool/impl.py", line 256, in _do_get
    return self._create_connection()
           ^^^^^^^^^^^^^^^^^^^^^^^^^
  File "/home/airflow/.local/lib/python3.11/site-packages/sqlalchemy/pool/base.py", line 273, in _create_connection
    return _ConnectionRecord(self)
           ^^^^^^^^^^^^^^^^^^^^^^^
  File "/home/airflow/.local/lib/python3.11/site-packages/sqlalchemy/pool/base.py", line 388, in __init__
    self.__connect()
  File "/home/airflow/.local/lib/python3.11/site-packages/sqlalchemy/pool/base.py", line 690, in __connect
    with util.safe_reraise():
  File "/home/airflow/.local/lib/python3.11/site-packages/sqlalchemy/util/langhelpers.py", line 70, in __exit__
    compat.raise_(
  File "/home/airflow/.local/lib/python3.11/site-packages/sqlalchemy/util/compat.py", line 211, in raise_
    raise exception
  File "/home/airflow/.local/lib/python3.11/site-packages/sqlalchemy/pool/base.py", line 686, in __connect
    self.dbapi_connection = connection = pool._invoke_creator(self)
                                         ^^^^^^^^^^^^^^^^^^^^^^^^^^
  File "/home/airflow/.local/lib/python3.11/site-packages/sqlalchemy/engine/create.py", line 574, in connect
    return dialect.connect(*cargs, **cparams)
           ^^^^^^^^^^^^^^^^^^^^^^^^^^^^^^^^^^
  File "/home/airflow/.local/lib/python3.11/site-packages/sqlalchemy/engine/default.py", line 598, in connect
    return self.dbapi.connect(*cargs, **cparams)
           ^^^^^^^^^^^^^^^^^^^^^^^^^^^^^^^^^^^^^
  File "/home/airflow/.local/lib/python3.11/site-packages/psycopg2/__init__.py", line 122, in connect
    conn = _connect(dsn, connection_factory=connection_factory, **kwasync)
           ^^^^^^^^^^^^^^^^^^^^^^^^^^^^^^^^^^^^^^^^^^^^^^^^^^^^^^^^^^^^^^^
sqlalchemy.exc.OperationalError: (psycopg2.OperationalError) could not translate host name "postgres" to address: Temporary failure in name resolution

(Background on this error at: https://sqlalche.me/e/14/e3q8)
[2024-10-24T01:33:59.603+0000] {job.py:219} ERROR - Job heartbeat got an exception
Traceback (most recent call last):
  File "/home/airflow/.local/lib/python3.11/site-packages/sqlalchemy/engine/base.py", line 3371, in _wrap_pool_connect
    return fn()
           ^^^^
  File "/home/airflow/.local/lib/python3.11/site-packages/sqlalchemy/pool/base.py", line 327, in connect
    return _ConnectionFairy._checkout(self)
           ^^^^^^^^^^^^^^^^^^^^^^^^^^^^^^^^
  File "/home/airflow/.local/lib/python3.11/site-packages/sqlalchemy/pool/base.py", line 894, in _checkout
    fairy = _ConnectionRecord.checkout(pool)
            ^^^^^^^^^^^^^^^^^^^^^^^^^^^^^^^^
  File "/home/airflow/.local/lib/python3.11/site-packages/sqlalchemy/pool/base.py", line 493, in checkout
    rec = pool._do_get()
          ^^^^^^^^^^^^^^
  File "/home/airflow/.local/lib/python3.11/site-packages/sqlalchemy/pool/impl.py", line 256, in _do_get
    return self._create_connection()
           ^^^^^^^^^^^^^^^^^^^^^^^^^
  File "/home/airflow/.local/lib/python3.11/site-packages/sqlalchemy/pool/base.py", line 273, in _create_connection
    return _ConnectionRecord(self)
           ^^^^^^^^^^^^^^^^^^^^^^^
  File "/home/airflow/.local/lib/python3.11/site-packages/sqlalchemy/pool/base.py", line 388, in __init__
    self.__connect()
  File "/home/airflow/.local/lib/python3.11/site-packages/sqlalchemy/pool/base.py", line 690, in __connect
    with util.safe_reraise():
  File "/home/airflow/.local/lib/python3.11/site-packages/sqlalchemy/util/langhelpers.py", line 70, in __exit__
    compat.raise_(
  File "/home/airflow/.local/lib/python3.11/site-packages/sqlalchemy/util/compat.py", line 211, in raise_
    raise exception
  File "/home/airflow/.local/lib/python3.11/site-packages/sqlalchemy/pool/base.py", line 686, in __connect
    self.dbapi_connection = connection = pool._invoke_creator(self)
                                         ^^^^^^^^^^^^^^^^^^^^^^^^^^
  File "/home/airflow/.local/lib/python3.11/site-packages/sqlalchemy/engine/create.py", line 574, in connect
    return dialect.connect(*cargs, **cparams)
           ^^^^^^^^^^^^^^^^^^^^^^^^^^^^^^^^^^
  File "/home/airflow/.local/lib/python3.11/site-packages/sqlalchemy/engine/default.py", line 598, in connect
    return self.dbapi.connect(*cargs, **cparams)
           ^^^^^^^^^^^^^^^^^^^^^^^^^^^^^^^^^^^^^
  File "/home/airflow/.local/lib/python3.11/site-packages/psycopg2/__init__.py", line 122, in connect
    conn = _connect(dsn, connection_factory=connection_factory, **kwasync)
           ^^^^^^^^^^^^^^^^^^^^^^^^^^^^^^^^^^^^^^^^^^^^^^^^^^^^^^^^^^^^^^^
psycopg2.OperationalError: could not translate host name "postgres" to address: Temporary failure in name resolution


The above exception was the direct cause of the following exception:

Traceback (most recent call last):
  File "/home/airflow/.local/lib/python3.11/site-packages/airflow/jobs/job.py", line 190, in heartbeat
    session.merge(self)
  File "/home/airflow/.local/lib/python3.11/site-packages/sqlalchemy/orm/session.py", line 3056, in merge
    return self._merge(
           ^^^^^^^^^^^^
  File "/home/airflow/.local/lib/python3.11/site-packages/sqlalchemy/orm/session.py", line 3136, in _merge
    merged = self.get(
             ^^^^^^^^^
  File "/home/airflow/.local/lib/python3.11/site-packages/sqlalchemy/orm/session.py", line 2853, in get
    return self._get_impl(
           ^^^^^^^^^^^^^^^
  File "/home/airflow/.local/lib/python3.11/site-packages/sqlalchemy/orm/session.py", line 2975, in _get_impl
    return db_load_fn(
           ^^^^^^^^^^^
  File "/home/airflow/.local/lib/python3.11/site-packages/sqlalchemy/orm/loading.py", line 530, in load_on_pk_identity
    session.execute(
  File "/home/airflow/.local/lib/python3.11/site-packages/sqlalchemy/orm/session.py", line 1716, in execute
    conn = self._connection_for_bind(bind)
           ^^^^^^^^^^^^^^^^^^^^^^^^^^^^^^^
  File "/home/airflow/.local/lib/python3.11/site-packages/sqlalchemy/orm/session.py", line 1555, in _connection_for_bind
    return self._transaction._connection_for_bind(
           ^^^^^^^^^^^^^^^^^^^^^^^^^^^^^^^^^^^^^^^
  File "/home/airflow/.local/lib/python3.11/site-packages/sqlalchemy/orm/session.py", line 750, in _connection_for_bind
    conn = bind.connect()
           ^^^^^^^^^^^^^^
  File "/home/airflow/.local/lib/python3.11/site-packages/sqlalchemy/future/engine.py", line 406, in connect
    return super(Engine, self).connect()
           ^^^^^^^^^^^^^^^^^^^^^^^^^^^^^
  File "/home/airflow/.local/lib/python3.11/site-packages/sqlalchemy/engine/base.py", line 3325, in connect
    return self._connection_cls(self, close_with_result=close_with_result)
           ^^^^^^^^^^^^^^^^^^^^^^^^^^^^^^^^^^^^^^^^^^^^^^^^^^^^^^^^^^^^^^^
  File "/home/airflow/.local/lib/python3.11/site-packages/sqlalchemy/engine/base.py", line 96, in __init__
    else engine.raw_connection()
         ^^^^^^^^^^^^^^^^^^^^^^^
  File "/home/airflow/.local/lib/python3.11/site-packages/sqlalchemy/engine/base.py", line 3404, in raw_connection
    return self._wrap_pool_connect(self.pool.connect, _connection)
           ^^^^^^^^^^^^^^^^^^^^^^^^^^^^^^^^^^^^^^^^^^^^^^^^^^^^^^^
  File "/home/airflow/.local/lib/python3.11/site-packages/sqlalchemy/engine/base.py", line 3374, in _wrap_pool_connect
    Connection._handle_dbapi_exception_noconnection(
  File "/home/airflow/.local/lib/python3.11/site-packages/sqlalchemy/engine/base.py", line 2208, in _handle_dbapi_exception_noconnection
    util.raise_(
  File "/home/airflow/.local/lib/python3.11/site-packages/sqlalchemy/util/compat.py", line 211, in raise_
    raise exception
  File "/home/airflow/.local/lib/python3.11/site-packages/sqlalchemy/engine/base.py", line 3371, in _wrap_pool_connect
    return fn()
           ^^^^
  File "/home/airflow/.local/lib/python3.11/site-packages/sqlalchemy/pool/base.py", line 327, in connect
    return _ConnectionFairy._checkout(self)
           ^^^^^^^^^^^^^^^^^^^^^^^^^^^^^^^^
  File "/home/airflow/.local/lib/python3.11/site-packages/sqlalchemy/pool/base.py", line 894, in _checkout
    fairy = _ConnectionRecord.checkout(pool)
            ^^^^^^^^^^^^^^^^^^^^^^^^^^^^^^^^
  File "/home/airflow/.local/lib/python3.11/site-packages/sqlalchemy/pool/base.py", line 493, in checkout
    rec = pool._do_get()
          ^^^^^^^^^^^^^^
  File "/home/airflow/.local/lib/python3.11/site-packages/sqlalchemy/pool/impl.py", line 256, in _do_get
    return self._create_connection()
           ^^^^^^^^^^^^^^^^^^^^^^^^^
  File "/home/airflow/.local/lib/python3.11/site-packages/sqlalchemy/pool/base.py", line 273, in _create_connection
    return _ConnectionRecord(self)
           ^^^^^^^^^^^^^^^^^^^^^^^
  File "/home/airflow/.local/lib/python3.11/site-packages/sqlalchemy/pool/base.py", line 388, in __init__
    self.__connect()
  File "/home/airflow/.local/lib/python3.11/site-packages/sqlalchemy/pool/base.py", line 690, in __connect
    with util.safe_reraise():
  File "/home/airflow/.local/lib/python3.11/site-packages/sqlalchemy/util/langhelpers.py", line 70, in __exit__
    compat.raise_(
  File "/home/airflow/.local/lib/python3.11/site-packages/sqlalchemy/util/compat.py", line 211, in raise_
    raise exception
  File "/home/airflow/.local/lib/python3.11/site-packages/sqlalchemy/pool/base.py", line 686, in __connect
    self.dbapi_connection = connection = pool._invoke_creator(self)
                                         ^^^^^^^^^^^^^^^^^^^^^^^^^^
  File "/home/airflow/.local/lib/python3.11/site-packages/sqlalchemy/engine/create.py", line 574, in connect
    return dialect.connect(*cargs, **cparams)
           ^^^^^^^^^^^^^^^^^^^^^^^^^^^^^^^^^^
  File "/home/airflow/.local/lib/python3.11/site-packages/sqlalchemy/engine/default.py", line 598, in connect
    return self.dbapi.connect(*cargs, **cparams)
           ^^^^^^^^^^^^^^^^^^^^^^^^^^^^^^^^^^^^^
  File "/home/airflow/.local/lib/python3.11/site-packages/psycopg2/__init__.py", line 122, in connect
    conn = _connect(dsn, connection_factory=connection_factory, **kwasync)
           ^^^^^^^^^^^^^^^^^^^^^^^^^^^^^^^^^^^^^^^^^^^^^^^^^^^^^^^^^^^^^^^
sqlalchemy.exc.OperationalError: (psycopg2.OperationalError) could not translate host name "postgres" to address: Temporary failure in name resolution

(Background on this error at: https://sqlalche.me/e/14/e3q8)
[2024-10-24T01:34:02.337+0000] {spark_submit.py:524} INFO - 24/10/24 01:34:02 INFO StandaloneSchedulerBackend: SchedulerBackend is ready for scheduling beginning after reached minRegisteredResourcesRatio: 0.0
[2024-10-24T01:35:24.512+0000] {spark_submit.py:524} INFO - 24/10/24 01:35:24 INFO AsyncEventQueue: Process of event SparkListenerExecutorMetricsUpdate(driver,WrappedArray(),Map((-1,-1) -> org.apache.spark.executor.ExecutorMetrics@3fea957b)) by listener AppStatusListener took 1.335281068s.
[2024-10-24T01:35:24.589+0000] {local_task_job_runner.py:294} WARNING - State of this instance has been externally set to None. Terminating instance.
[2024-10-24T01:35:24.787+0000] {process_utils.py:131} INFO - Sending 15 to group 8908. PIDs of all processes in the group: [8975, 9602, 8908]
[2024-10-24T01:35:24.795+0000] {process_utils.py:86} INFO - Sending the signal 15 to group 8908
[2024-10-24T01:35:24.796+0000] {taskinstance.py:1630} ERROR - Received SIGTERM. Terminating subprocesses.
[2024-10-24T01:35:24.798+0000] {spark_submit.py:654} INFO - Sending kill signal to spark-submit
[2024-10-24T01:35:24.839+0000] {process_utils.py:79} INFO - Process psutil.Process(pid=9602, status='terminated', started='01:27:21') (9602) terminated with exit code None
[2024-10-24T01:35:25.123+0000] {taskinstance.py:1935} ERROR - Task failed with exception
Traceback (most recent call last):
  File "/home/airflow/.local/lib/python3.11/site-packages/airflow/providers/apache/spark/operators/spark_submit.py", line 183, in execute
    self._hook.submit(self._application)
  File "/home/airflow/.local/lib/python3.11/site-packages/airflow/providers/apache/spark/hooks/spark_submit.py", line 438, in submit
    self._process_spark_submit_log(iter(self._submit_sp.stdout))  # type: ignore
    ^^^^^^^^^^^^^^^^^^^^^^^^^^^^^^^^^^^^^^^^^^^^^^^^^^^^^^^^^^^^
  File "/home/airflow/.local/lib/python3.11/site-packages/airflow/providers/apache/spark/hooks/spark_submit.py", line 492, in _process_spark_submit_log
    for line in itr:
  File "/home/airflow/.local/lib/python3.11/site-packages/airflow/models/taskinstance.py", line 1632, in signal_handler
    raise AirflowException("Task received SIGTERM signal")
airflow.exceptions.AirflowException: Task received SIGTERM signal
[2024-10-24T01:35:25.189+0000] {taskinstance.py:1398} INFO - Marking task as UP_FOR_RETRY. dag_id=api_openbrewerydb_to_silver_gold, task_id=Silver, execution_date=20231203T080000, start_date=20241024T012658, end_date=20241024T013525
[2024-10-24T01:35:25.359+0000] {standard_task_runner.py:104} ERROR - Failed to execute job 142 for task Silver (Task received SIGTERM signal; 8908)
[2024-10-24T01:35:25.518+0000] {process_utils.py:79} INFO - Process psutil.Process(pid=8908, status='terminated', exitcode=1, started='01:26:58') (8908) terminated with exit code 1
[2024-10-24T01:35:25.519+0000] {process_utils.py:79} INFO - Process psutil.Process(pid=8975, status='terminated', started='01:26:59') (8975) terminated with exit code None
